{"name": "test_function", "status": "failed", "statusDetails": {"message": "AssertionError: 判断 a 为偶数，当前 a 的值为：3\nassert (3 % 2) == 0", "trace": "def test_function():\n        # assert f() == 4\n        a = f()\n>       assert a % 2 == 0, \"判断 a 为偶数，当前 a 的值为：%s\" %a\nE       AssertionError: 判断 a 为偶数，当前 a 的值为：3\nE       assert (3 % 2) == 0\n\ntest_assert1.py:9: AssertionError"}, "start": 1597305143983, "stop": 1597305143983, "uuid": "389c2aa0-d6e7-4206-89d0-49ad6a2e229b", "historyId": "c07f55d59f64ccfc8125eb6a533de7cc", "testCaseId": "210bc203de731bb4de9de75c7518fb56", "fullName": "test_assert1#test_function", "labels": [{"name": "suite", "value": "test_assert1"}, {"name": "host", "value": "PC-20160818TLFG"}, {"name": "thread", "value": "25396-MainThread"}, {"name": "framework", "value": "pytest"}, {"name": "language", "value": "cpython3"}, {"name": "package", "value": "test_assert1"}]}